<?xml version="1.0" encoding="utf-8"?>
<mujoco>
  <worldbody>
    <body name="left_arm" pos="0 0.355 0.82">
      <!-- A1 Robot 2 for inclusion -->
      <geom type="mesh" rgba="0.79216 0.81961 0.93333 1" mesh="base_link"/>
      <body name="left_arm_seg1" pos="-0.0011147 0 0.0892" quat="-3.67321e-06 0 0 1">
        <inertial pos="-1.4403e-06 -0.00074041 0.056573" quat="0.707084 0.00122867 -0.00107609 0.707127" mass="1.391" diaginertia="0.000708573 0.00058101 0.000445827"/>
        <joint name="left_arm_joint1" pos="0 0 0" axis="0 0 1" range="-2.8798 2.8798"/>
        <geom type="mesh" rgba="0.79216 0.81961 0.93333 1" mesh="arm_seg1"/>
        <body name="left_arm_seg2" pos="0 -4e-05 0.0615" quat="0.707105 0.707108 0 0">
          <inertial pos="0.23622 0.016356 9.154e-05" quat="0.484393 0.48518 0.524693 0.504639" mass="1.3" diaginertia="0.00761886 0.00757469 0.000578276"/>
          <joint name="left_arm_joint2" pos="0 0 0" axis="0 0 1" range="0 3.1415"/>
          <geom type="mesh" rgba="0.79216 0.81961 0.93333 1" mesh="arm_seg2"/>
          <body name="left_arm_seg3" pos="0.34928 0.02 0" quat="0.707105 0 0 0.707108">
            <inertial pos="0.054443 0.045347 0.00042807" quat="0.595278 0.471808 -0.522016 0.387995" mass="0.818" diaginertia="0.00149749 0.00144877 0.00053598"/>
            <joint name="left_arm_joint3" pos="0 0 0" axis="0 0 1" range="-3.3161 0"/>
            <geom type="mesh" rgba="0.79216 0.81961 0.93333 1" mesh="arm_seg3"/>
            <body name="left_arm_seg4" pos="0.07 -0.00395 -4e-05" quat="0.499998 -0.5 0.5 0.500002">
              <inertial pos="7.6256e-07 -0.0021448 0.27415" quat="0.70651 0.0169198 -0.0168252 0.707301" mass="0.816" diaginertia="0.000101779 9.7042e-05 8.44616e-05"/>
              <joint name="left_arm_joint4" pos="0 0 0" axis="0 0 1" range="-2.8798 2.8798"/>
              <geom type="mesh" rgba="1 1 1 1" mesh="arm_seg4"/>
              <body name="left_arm_seg5" pos="0 0 0.2776" quat="-2.59734e-06 2.59735e-06 -0.707108 0.707105">
                <inertial pos="-3.9997e-06 -0.05431 0.0034482" quat="0.477398 0.87868 0.00338218 -0.000840949" mass="0.801" diaginertia="0.00011332 0.000109027 7.34689e-05"/>
                <joint name="left_arm_joint5" pos="0 0 0" axis="0 0 1" range="-1.6581 1.6581"/>
                <geom type="mesh" rgba="1 1 1 1" mesh="arm_seg5"/>
                <body name="left_arm_seg6" pos="0 -0.1575 -0.00023266" quat="0.707105 0.707108 0 0">
                  <inertial pos="-0.0113206 0.00196256 0.0176711" quat="0.583625 -0.0526594 0.0473525 0.808929" mass="1.46952" diaginertia="0.00398591 0.00337199 0.00122082"/>
                  <joint name="left_arm_joint6" pos="0 0 0" axis="0 0 1" range="-2.8798 2.8798"/>
                  <geom type="mesh" rgba="0.79216 0.81961 0.93333 1" mesh="arm_seg6"/>
                  <geom pos="0 0 -0.063796" quat="1 0 0 0" type="mesh" rgba="0.75294 0.75294 0.75294 0.25" mesh="galaxea_eoat_set"/>
                  <geom pos="0.092689 0 -0.010838" quat="0.965926 0 -0.25882 0" type="mesh" rgba="0.752941 0.752941 0.752941 1" mesh="camera"/>
                  <body name="left_camera_body" pos="0.092689 0 -0.010838" quat="0.965926 0 -0.258819 0">
                    <body name="left_tilt_down" pos="0 0 0" quat="0.9981 0 -0.0611 0">
                      <camera name="eoat_left_top" pos="0 0 0.01" quat="0 0.7071 0.7071 0" fovy="60"/>
                      <site name="left_camera_marker" pos="0 0 0.01" type="sphere" size="0.005" rgba="1 0 0 0"/>
                    </body>
                  </body>
                  <body name="left_left_finger" pos="0.00025714 0.041492 0.005904">
                    <inertial pos="-3.90917e-05 -0.0064925 0.0207255" quat="0.707102 0.0633636 -0.0633458 0.701412" mass="0.0920111" diaginertia="3.78659e-05 3.48288e-05 6.45297e-06"/>
                    <joint name="left_gripper1_axis" pos="0 0 0" axis="0.0014394 1.0 0" type="slide" range="0 0.025"/>
                    <geom type="mesh" rgba="0.752941 0.752941 0.752941 1" mesh="left_finger"/>
                  </body>
                  <site name="left_tool_pose" pos="0.0 0 0.06" type="sphere" size="0.01" rgba="1 1 0 0"/>
                  <body name="left_right_finger" pos="0.00014129 -0.041492 0.005904">
                    <inertial pos="3.911e-05 0.00648979 0.020716" quat="0.707103 -0.0633291 0.0633118 0.701417" mass="0.091987" diaginertia="3.78279e-05 3.47909e-05 6.45217e-06"/>
                    <joint name="left_gripper2_axis" pos="0 0 0" axis="-0.0014394 -1.0 0" type="slide" range="0 0.025"/>
                    <geom type="mesh" rgba="0.752941 0.752941 0.752941 1" mesh="right_finger"/>
                  </body>
                </body>
              </body>
            </body>
          </body>
        </body>
      </body>
    </body>
  </worldbody>
  <equality>
    <joint joint1="left_gripper1_axis" joint2="left_gripper2_axis" polycoef="0 1 -1 0 0"/>
  </equality>
  <actuator>
    <!-- Arm Actuators -->
    <position name="left_joint1" joint="left_arm_joint1" kp="40"/>
    <position name="left_joint2" joint="left_arm_joint2" kp="40"/>
    <position name="left_joint3" joint="left_arm_joint3" kp="27"/>
    <position name="left_joint4" joint="left_arm_joint4" kp="7"/>
    <position name="left_joint5" joint="left_arm_joint5" kp="7"/>
    <position name="left_joint6" joint="left_arm_joint6" kp="7"/>
    <!-- Gripper Actuator -->
    <position name="left_gripper" joint="left_gripper1_axis" kp="200" ctrlrange="0 0.025"/>
  </actuator>
</mujoco>